Workbook

Sheet Master Data
A1: ADANI GREEN ENERGY LIMITED — Project Master Tracker
A2: Project ID | B2: Project Name | C2: Project Type | D2: Location | E2: State | F2: Capacity (MW) | G2: FY Year | H2: Category | I2: Budget Allocated (₹ Cr) | J2: Budget Used (₹ Cr) | K2: Budget Remaining (₹ Cr) | L2: Revenue Generated (₹ Cr) | M2: Scheduled Comm. Date | N2: Expected Comm. Date | O2: Actual Comm. Date | P2: Contractor Name | Q2: Material (Module/Turbine) | R2: Material Status | S2: Contractor Payment Status | T2: Project Completion (%) | U2: Delay (Days) | V2: Remarks
A3: AGEL-S-001 | B3: Tumkur Solar Phase 3 – 200MW | C3: Solar | D3: Tumkur | E3: Karnataka | F3: 200 | G3: FY2023-24 | H3: Commissioned | I3: 983.75 | J3: 926.94 | K3: =I3-J3 -> 56.81 | L3: 262.59 | M3: 12-Apr-2023 | N3: — | O3: 10-May-2023 | P3: Goldi Solar Pvt Ltd | Q3: JA Solar (545W DeepBlue) | R3: Fully Delivered | S3: Fully Paid | T3: 1 | U3: 0 | V3: On track
A4: AGEL-S-002 | B4: Chitradurga Solar Park – 250MW | C4: Solar | D4: Chitradurga | E4: Karnataka | F4: 250 | G4: FY2022-23 | H4: Commissioned | I4: 1201.97 | J4: 1140.33 | K4: =I4-J4 -> 61.64 | L4: 257.7 | M4: 18-Jul-2021 | N4: — | O4: 29-Jul-2021 | P4: Sterling and Wilson Pvt Ltd | Q4: Jinko Solar (545W Tiger Neo) | R4: Fully Delivered | S4: 75% Paid – Balance on Completion | T4: 1 | U4: 0 | V4: On track
A5: AGEL-S-003 | B5: Pokhran Solar Phase 2 – 100MW | C5: Solar | D5: Pokhran | E5: Rajasthan | F5: 100 | G5: FY2021-22 | H5: Commissioned | I5: 518.96 | J5: 513.22 | K5: =I5-J5 -> 5.74 | L5: 123.38 | M5: 05-Jun-2022 | N5: — | O5: 24-Aug-2022 | P5: Sterling and Wilson Pvt Ltd | Q5: Trina Solar (550W Vertex) | R5: Fully Delivered | S5: Fully Paid | T5: 1 | U5: 0 | V5: On track
A6: AGEL-S-004 | B6: Jodhpur Solar Phase 1 – 250MW | C6: Solar | D6: Jodhpur | E6: Rajasthan | F6: 250 | G6: FY2021-22 | H6: Commissioned | I6: 1231.36 | J6: 1215.02 | K6: =I6-J6 -> 16.34 | L6: 241.67 | M6: 14-Jan-2023 | N6: — | O6: 18-Feb-2023 | P6: KEC International | Q6: LONGi Solar (555W Hi-MO6) | R6: Fully Delivered | S6: 75% Paid – Balance on Completion | T6: 1 | U6: 0 | V6: On track
A7: AGEL-S-005 | B7: Mundra Solar Phase 1 – 100MW | C7: Solar | D7: Mundra | E7: Gujarat | F7: 100 | G7: FY2023-24 | H7: Commissioned | I7: 493.96 | J7: 465.11 | K7: =I7-J7 -> 28.85 | L7: 134.62 | M7: 27-Apr-2022 | N7: — | O7: 17-May-2022 | P7: Vikram Solar Ltd | Q7: Waaree Energies (550W Mono PERC) | R7: Fully Delivered | S7: Fully Paid | T7: 1 | U7: 0 | V7: On track
A8: AGEL-S-006 | B8: Patan Solar Phase 2 – 200MW | C8: Solar | D8: Patan | E8: Gujarat | F8: 200 | G8: FY2022-23 | H8: Commissioned | I8: 907.51 | J8: 903.37 | K8: =I8-J8 -> 4.14 | L8: 242.88 | M8: 25-Jun-2022 | N8: — | O8: 03-Jul-2022 | P8: KEC International | Q8: Jinko Solar (545W Tiger Neo) | R8: Fully Delivered | S8: 75% Paid – Balance on Completion | T8: 1 | U8: 0 | V8: On track
A9: AGEL-S-007 | B9: Osmanabad Solar Phase 3 – 400MW | C9: Solar | D9: Osmanabad | E9: Maharashtra | F9: 400 | G9: FY2022-23 | H9: Commissioned | I9: 1769.36 | J9: 1733.26 | K9: =I9-J9 -> 36.1 | L9: 413.85 | M9: 17-Sep-2021 | N9: — | O9: 20-Oct-2021 | P9: Genus Power Infrastructures | Q9: Canadian Solar (550W HiKu7) | R9: Fully Delivered | S9: 75% Paid – Balance on Completion | T9: 1 | U9: 0 | V9: On track
A10: AGEL-S-008 | B10: Morbi Solar Park – 300MW | C10: Solar | D10: Morbi | E10: Gujarat | F10: 300 | G10: FY2021-22 | H10: Commissioned | I10: 1303.64 | J10: 1204.26 | K10: =I10-J10 -> 99.38 | L10: 248.95 | M10: 08-Sep-2023 | N10: — | O10: 10-Nov-2023 | P10: Goldi Solar Pvt Ltd | Q10: REC Group (405W Alpha Pure-R) | R10: Fully Delivered | S10: Fully Paid | T10: 1 | U10: 0 | V10: On track
A11: AGEL-S-009 | B11: Anantapur Solar Park – 100MW | C11: Solar | D11: Anantapur | E11: Andhra Pradesh | F11: 100 | G11: FY2023-24 | H11: Commissioned | I11: 460.23 | J11: 443.78 | K11: =I11-J11 -> 16.45 | L11: 126.21 | M11: 11-Jun-2023 | N11: — | O11: 17-Aug-2023 | P11: SPML Infra Ltd | Q11: LONGi Solar (555W Hi-MO6) | R11: Fully Delivered | S11: Fully Paid | T11: 1 | U11: 0 | V11: On track
A12: AGEL-S-010 | B12: Rann of Kutch Solar Park – 300MW | C12: Solar | D12: Rann of Kutch | E12: Gujarat | F12: 300 | G12: FY2022-23 | H12: Commissioned | I12: 1261.56 | J12: 1233.51 | K12: =I12-J12 -> 28.05 | L12: 317.87 | M12: 23-Sep-2021 | N12: — | O12: 20-Nov-2021 | P12: SPML Infra Ltd | Q12: Adani Solar (540W TOPCon) | R12: Fully Delivered | S12: Fully Paid | T12: 1 | U12: 0 | V12: On track
A13: AGEL-S-011 | B13: Jaisalmer Solar Phase 3 – 250MW | C13: Solar | D13: Jaisalmer | E13: Rajasthan | F13: 250 | G13: FY2023-24 | H13: Commissioned | I13: 1199.57 | J13: 1119.11 | K13: =I13-J13 -> 80.46 | L13: 330.3 | M13: 24-Jan-2022 | N13: — | O13: 12-Feb-2022 | P13: Genus Power Infrastructures | Q13: JA Solar (545W DeepBlue) | R13: Fully Delivered | S13: Fully Paid | T13: 1 | U13: 0 | V13: On track
A14: AGEL-S-012 | B14: Kurnool Solar Park – 500MW | C14: Solar | D14: Kurnool | E14: Andhra Pradesh | F14: 500 | G14: FY2022-23 | H14: Commissioned | I14: 2146.34 | J14: 2125.39 | K14: =I14-J14 -> 20.95 | L14: 589.59 | M14: 23-Aug-2022 | N14: — | O14: 22-Sep-2022 | P14: Montecarlo Ltd | Q14: Adani Solar (540W TOPCon) | R14: Fully Delivered | S14: Fully Paid | T14: 1 | U14: 0 | V14: On track
... A32: AGEL-S-030 | B32: Kurnool Solar Phase 2 – 200MW | C32: Solar | D32: Kurnool | E32: Andhra Pradesh | F32: 200 | G32: FY2023-24 | H32: Commissioned | I32: 1079.83 | J32: 1073.42 | K32: =I32-J32 -> 6.41 | L32: 219.93 | M32: 24-Jan-2023 | N32: — | O32: 13-Apr-2023 | P32: L&T Construction | Q32: Canadian Solar (550W HiKu7) | R32: Fully Delivered | S32: Fully Paid | T32: 1 | U32: 0 | V32: On track
A33: AGEL-S-031 | B33: Bikaner Solar Park – 50MW | C33: Solar | D33: Bikaner | E33: Rajasthan | F33: 50 | G33: FY2025-26 | H33: Ongoing | I33: 250.24 | J33: 163.73 | K33: =I33-J33 -> 86.51 | L33: 0 | M33: 26-Feb-2026 | N33: 19-Oct-2026 | O33: — | P33: Tata Projects Ltd | Q33: Canadian Solar (550W HiKu7) | R33: Partially Delivered – 25% | S33: 50% Paid – Milestone 2 Pending | T33: 0.51 | U33: =IF(N33="—",0,IF(M33="—",0,IFERROR(DATEVALUE(N33)-DATEVALUE(M33),0))) -> 235 | V33: Land acquisition in progress
A34: AGEL-S-032 | B34: Pavagada Solar Park – 500MW | C34: Solar | D34: Pavagada | E34: Karnataka | F34: 500 | G34: FY2025-26 | H34: Ongoing | I34: 2615.4 | J34: 1907.22 | K34: =I34-J34 -> 708.18 | L34: 0 | M34: 25-Dec-2025 | N34: 12-Apr-2026 | O34: — | P34: Goldi Solar Pvt Ltd | Q34: JA Solar (545W DeepBlue) | R34: Partially Delivered – 75% | S34: 50% Paid – Milestone 2 Pending | T34: 0.48 | U34: =IF(N34="—",0,IF(M34="—",0,IFERROR(DATEVALUE(N34)-DATEVALUE(M34),0))) -> 108 | V34: Transmission line work pending
A35: AGEL-S-033 | B35: Dhule Solar Phase 2 – 100MW | C35: Solar | D35: Dhule | E35: Maharashtra | F35: 100 | G35: FY2025-26 | H35: Ongoing | I35: 459.95 | J35: 363.19 | K35: =I35-J35 -> 96.76 | L35: 0 | M35: 19-Oct-2026 | N35: 28-Mar-2027 | O35: — | P35: Waaree Energies Ltd | Q35: Vikram Solar (545W HJT) | R35: Partially Delivered – 75% | S35: 75% Paid – Balance on Completion | T35: 0.62 | U35: =IF(N35="—",0,IF(M35="—",0,IFERROR(DATEVALUE(N35)-DATEVALUE(M35),0))) -> 160 | V35: Transmission line work pending
A36: AGEL-S-034 | B36: Barmer Solar Park – 50MW | C36: Solar | D36: Barmer | E36: Rajasthan | F36: 50 | G36: FY2025-26 | H36: Ongoing | I36: 258.98 | J36: 126.9 | K36: =I36-J36 -> 132.08 | L36: 0 | M36: 20-Dec-2025 | N36: 24-Jul-2026 | O36: — | P36: Genus Power Infrastructures | Q36: Trina Solar (550W Vertex) | R36: Partially Delivered – 75% | S36: 10% Mobilisation Advance Paid | T36: 0.85 | U36: =IF(N36="—",0,IF(M36="—",0,IFERROR(DATEVALUE(N36)-DATEVALUE(M36),0))) -> 216 | V36: Transmission line work pending
A37: AGEL-S-035 | B37: Khavda Solar Phase 1 – 50MW | C37: Solar | D37: Khavda | E37: Gujarat | F37: 50 | G37: FY2024-25 | H37: Ongoing | I37: 205.25 | J37: 126.3 | K37: =I37-J37 -> 78.95 | L37: 0 | M37: 08-Jan-2026 | N37: 28-May-2026 | O37: — | P37: Tata Projects Ltd | Q37: LONGi Solar (555W Hi-MO6) | R37: PO Raised – Awaiting Dispatch | S37: 30% Paid – Advance Released | T37: 0.62 | U37: =IF(N37="—",0,IF(M37="—",0,IFERROR(DATEVALUE(N37)-DATEVALUE(M37),0))) -> 140 | V37: Transmission line work pending
A38: AGEL-S-036 | B38: Fatehgarh Solar Park – 400MW | C38: Solar | D38: Fatehgarh | E38: Rajasthan | F38: 400 | G38: FY2025-26 | H38: Ongoing | I38: 1715.1 | J38: 1056.01 | K38: =I38-J38 -> 659.09 | L38: 0 | M38: 22-Jul-2026 | N38: 22-Sep-2026 | O38: — | P38: Genus Power Infrastructures | Q38: LONGi Solar (555W Hi-MO6) | R38: Partially Delivered – 50% | S38: Payment on Hold – Dispute | T38: 0.68 | U38: =IF(N38="—",0,IF(M38="—",0,IFERROR(DATEVALUE(N38)-DATEVALUE(M38),0))) -> 62 | V38: Turbine erection in progress
A39: AGEL-S-037 | B39: Tumkur Solar Park – 50MW | C39: Solar | D39: Tumkur | E39: Karnataka | F39: 50 | G39: FY2024-25 | H39: Ongoing | I39: 243.5 | J39: 148.56 | K39: =I39-J39 -> 94.94 | L39: 0 | M39: 17-Mar-2026 | N39: 03-Nov-2026 | O39: — | P39: KEC International | Q39: First Solar (440W Series 6) | R39: In Transit | S39: 10% Mobilisation Advance Paid | T39: 0.79 | U39: =IF(N39="—",0,IF(M39="—",0,IFERROR(DATEVALUE(N39)-DATEVALUE(M39),0))) -> 231 | V39: Statutory approvals awaited
A40: AGEL-S-038 | B40: Chitradurga Solar Phase 2 – 150MW | C40: Solar | D40: Chitradurga | E40: Karnataka | F40: 150 | G40: FY2025-26 | H40: Ongoing | I40: 814.2 | J40: 308.73 | K40: =I40-J40 -> 505.47 | L40: 0 | M40: 06-Apr-2025 | N40: 01-Dec-2025 | O40: — | P40: L&T Construction | Q40: Waaree Energies (550W Mono PERC) | R40: Partially Delivered – 50% | S40: 50% Paid – Milestone 2 Pending | T40: 0.59 | U40: =IF(N40="—",0,IF(M40="—",0,IFERROR(DATEVALUE(N40)-DATEVALUE(M40),0))) -> 239 | V40: Land acquisition in progress
A41: AGEL-S-039 | B41: Pokhran Solar Phase 3 – 200MW | C41: Solar | D41: Pokhran | E41: Rajasthan | F41: 200 | G41: FY2024-25 | H41: Ongoing | I41: 1065.84 | J41: 603.93 | K41: =I41-J41 -> 461.91 | L41: 0 | M41: 12-Apr-2026 | N41: 26-Aug-2026 | O41: — | P41: KEC International | Q41: Vikram Solar (545W HJT) | R41: In Transit | S41: 10% Mobilisation Advance Paid | T41: 0.69 | U41: =IF(N41="—",0,IF(M41="—",0,IFERROR(DATEVALUE(N41)-DATEVALUE(M41),0))) -> 136 | V41: Land acquisition in progress
A42: AGEL-S-040 | B42: Jodhpur Solar Phase 1 – 100MW | C42: Solar | D42: Jodhpur | E42: Rajasthan | F42: 100 | G42: FY2024-25 | H42: Ongoing | I42: 469.68 | J42: 261.41 | K42: =I42-J42 -> 208.27 | L42: 0 | M42: 14-Dec-2026 | N42: 25-May-2027 | O42: — | P42: Montecarlo Ltd | Q42: First Solar (440W Series 6) | R42: In Transit | S42: 50% Paid – Milestone 2 Pending | T42: 0.35 | U42: =IF(N42="—",0,IF(M42="—",0,IFERROR(DATEVALUE(N42)-DATEVALUE(M42),0))) -> 162 | V42: Financial closure in progress
A43: AGEL-S-041 | B43: Mundra Solar Phase 3 – 500MW | C43: Solar | D43: Mundra | E43: Gujarat | F43: 500 | G43: FY2025-26 | H43: Ongoing | I43: 2672.91 | J43: 1761.48 | K43: =I43-J43 -> 911.43 | L43: 0 | M43: 16-Jul-2026 | N43: 07-Dec-2026 | O43: — | P43: KEC International | Q43: LONGi Solar (555W Hi-MO6) | R43: In Transit | S43: 30% Paid – Advance Released | T43: 0.8 | U43: =IF(N43="—",0,IF(M43="—",0,IFERROR(DATEVALUE(N43)-DATEVALUE(M43),0))) -> 144 | V43: Statutory approvals awaited
A44: AGEL-S-042 | B44: Patan Solar Park – 200MW | C44: Solar | D44: Patan | E44: Gujarat | F44: 200 | G44: FY2024-25 | H44: Ongoing | I44: 881.51 | J44: 375.38 | K44: =I44-J44 -> 506.13 | L44: 0 | M44: 20-Oct-2025 | N44: 18-Jan-2026 | O44: — | P44: KEC International | Q44: Canadian Solar (550W HiKu7) | R44: Partially Delivered – 50% | S44: 50% Paid – Milestone 2 Pending | T44: 0.3 | U44: =IF(N44="—",0,IF(M44="—",0,IFERROR(DATEVALUE(N44)-DATEVALUE(M44),0))) -> 90 | V44: Civil work ongoing
... A57: AGEL-S-055 | B57: Tumkur Solar Park – 100MW | C57: Solar | D57: Tumkur | E57: Karnataka | F57: 100 | G57: FY2026-27 | H57: Planned | I57: 422.87 | J57: 24.59 | K57: =I57-J57 -> 398.28 | L57: 0 | M57: 10-Dec-2027 | N57: 09-Oct-2028 | O57: — | P57: Vikram Solar Ltd | Q57: Canadian Solar (550W HiKu7) | R57: Not Yet Procured | S57: Not Started | T57: 0.15 | U57: =IF(N57="—",0,IF(M57="—",0,IFERROR(DATEVALUE(N57)-DATEVALUE(M57),0))) -> 304 | V57: Financial closure in progress
A58: AGEL-W-056 | B58: Khavda Wind Phase 2 – 50MW | C58: Wind | D58: Khavda | E58: Gujarat | F58: 50 | G58: FY2021-22 | H58: Commissioned | I58: 234.18 | J58: 228.71 | K58: =I58-J58 -> 5.47 | L58: 45.12 | M58: 19-Dec-2022 | N58: — | O58: 10-Jan-2023 | P58: Suzlon Energy Ltd | Q58: Vestas V150-4.5MW | R58: Fully Delivered | S58: Fully Paid | T58: 1 | U58: 0 | V58: On track
A59: AGEL-W-057 | B59: Jodhpur Wind Phase 3 – 300MW | C59: Wind | D59: Jodhpur | E59: Rajasthan | F59: 300 | G59: FY2022-23 | H59: Commissioned | I59: 1535.55 | J59: 1470.37 | K59: =I59-J59 -> 65.18 | L59: 344.04 | M59: 29-Jul-2021 | N59: — | O59: 30-Jul-2021 | P59: Suzlon Energy Ltd | Q59: Vestas V150-4.5MW | R59: Fully Delivered | S59: Fully Paid | T59: 1 | U59: 0 | V59: On track
A60: AGEL-W-058 | B60: Tumkur Wind Park – 200MW | C60: Wind | D60: Tumkur | E60: Karnataka | F60: 200 | G60: FY2021-22 | H60: Commissioned | I60: 863.71 | J60: 838.11 | K60: =I60-J60 -> 25.6 | L60: 160.1 | M60: 29-Jan-2023 | N60: — | O60: 01-Apr-2023 | P60: Senvion India Pvt Ltd | Q60: Vestas V150-4.5MW | R60: Fully Delivered | S60: Fully Paid | T60: 1 | U60: 0 | V60: On track
A61: AGEL-W-059 | B61: Patan Wind Phase 1 – 50MW | C61: Wind | D61: Patan | E61: Gujarat | F61: 50 | G61: FY2023-24 | H61: Commissioned | I61: 257.69 | J61: 249.82 | K61: =I61-J61 -> 7.87 | L61: 66.37 | M61: 15-Feb-2023 | N61: — | O61: 03-May-2023 | P61: Envision Energy India | Q61: Windworld W-3000 | R61: Fully Delivered | S61: 75% Paid – Balance on Completion | T61: 1 | U61: 0 | V61: On track
A62: AGEL-W-060 | B62: Anantapur Wind Phase 2 – 150MW | C62: Wind | D62: Anantapur | E62: Andhra Pradesh | F62: 150 | G62: FY2022-23 | H62: Commissioned | I62: 860.43 | J62: 798.43 | K62: =I62-J62 -> 62 | L62: 220.51 | M62: 15-Feb-2021 | N62: — | O62: 04-May-2021 | P62: GE Vernova India | Q62: Siemens Gamesa SG 5.0-145 | R62: Fully Delivered | S62: Fully Paid | T62: 1 | U62: 0 | V62: On track
A63: AGEL-W-061 | B63: Morbi Wind Park – 100MW | C63: Wind | D63: Morbi | E63: Gujarat | F63: 100 | G63: FY2023-24 | H63: Commissioned | I63: 420.43 | J63: 401.95 | K63: =I63-J63 -> 18.48 | L63: 100.64 | M63: 14-May-2021 | N63: — | O63: 03-Jun-2021 | P63: Suzlon Energy Ltd | Q63: GE Vernova 3.6MW-137 | R63: Fully Delivered | S63: 75% Paid – Balance on Completion | T63: 1 | U63: 0 | V63: On track
A64: AGEL-W-062 | B64: Rann of Kutch Wind Phase 3 – 150MW | C64: Wind | D64: Rann of Kutch | E64: Gujarat | F64: 150 | G64: FY2022-23 | H64: Commissioned | I64: 686.02 | J64: 645.66 | K64: =I64-J64 -> 40.36 | L64: 177.76 | M64: 28-Feb-2021 | N64: — | O64: 26-May-2021 | P64: ReGen Powertech Pvt Ltd | Q64: Siemens Gamesa SG 5.0-145 | R64: Fully Delivered | S64: Fully Paid | T64: 1 | U64: 0 | V64: On track
A65: AGEL-W-063 | B65: Bikaner Wind Park – 250MW | C65: Wind | D65: Bikaner | E65: Rajasthan | F65: 250 | G65: FY2021-22 | H65: Commissioned | I65: 1078.56 | J65: 1006.59 | K65: =I65-J65 -> 71.97 | L65: 227.32 | M65: 11-Jun-2022 | N65: — | O65: 29-Jun-2022 | P65: Envision Energy India | Q65: Siemens Gamesa SG 5.0-145 | R65: Fully Delivered | S65: 75% Paid – Balance on Completion | T65: 1 | U65: 0 | V65: On track
A66: AGEL-W-064 | B66: Dhule Wind Phase 3 – 200MW | C66: Wind | D66: Dhule | E66: Maharashtra | F66: 200 | G66: FY2022-23 | H66: Commissioned | I66: 1012.79 | J66: 967.24 | K66: =I66-J66 -> 45.55 | L66: 242.87 | M66: 09-May-2022 | N66: — | O66: 12-Jul-2022 | P66: Windworld India Ltd | Q66: Vestas V150-4.5MW | R66: Fully Delivered | S66: 75% Paid – Balance on Completion | T66: 1 | U66: 0 | V66: On track
A67: AGEL-W-065 | B67: Mundra Wind Park – 50MW | C67: Wind | D67: Mundra | E67: Gujarat | F67: 50 | G67: FY2023-24 | H67: Commissioned | I67: 275.71 | J67: 266.36 | K67: =I67-J67 -> 9.35 | L67: 70.67 | M67: 18-Nov-2020 | N67: — | O67: 12-Feb-2021 | P67: Envision Energy India | Q67: Windworld W-3000 | R67: Fully Delivered | S67: Fully Paid | T67: 1 | U67: 0 | V67: On track
A68: AGEL-W-066 | B68: Chitradurga Wind Park – 150MW | C68: Wind | D68: Chitradurga | E68: Karnataka | F68: 150 | G68: FY2025-26 | H68: Ongoing | I68: 710.64 | J68: 213.32 | K68: =I68-J68 -> 497.32 | L68: 0 | M68: 13-Oct-2026 | N68: 08-Jun-2027 | O68: — | P68: Windworld India Ltd | Q68: Siemens Gamesa SG 5.0-145 | R68: In Transit | S68: 30% Paid – Advance Released | T68: 0.64 | U68: =IF(N68="—",0,IF(M68="—",0,IFERROR(DATEVALUE(N68)-DATEVALUE(M68),0))) -> 238 | V68: Civil work ongoing
A69: AGEL-W-067 | B69: Jaisalmer Wind Phase 2 – 150MW | C69: Wind | D69: Jaisalmer | E69: Rajasthan | F69: 150 | G69: FY2025-26 | H69: Ongoing | I69: 783.05 | J69: 432.68 | K69: =I69-J69 -> 350.37 | L69: 0 | M69: 10-Nov-2026 | N69: 22-Mar-2027 | O69: — | P69: GE Vernova India | Q69: Enercon E-160 EP5 | R69: Partially Delivered – 75% | S69: 30% Paid – Advance Released | T69: 0.78 | U69: =IF(N69="—",0,IF(M69="—",0,IFERROR(DATEVALUE(N69)-DATEVALUE(M69),0))) -> 132 | V69: Pending grid connectivity approval
...

Sheet Summary Dashboard
A1: AGEL — Executive Project Summary Dashboard
A2: Portfolio Overview
A3: Total Projects | B3: =COUNTA('Master Data'!A3:A77) -> 75
A4: Solar Projects | B4: =COUNTIF('Master Data'!C3:C77,"Solar") -> 55
A5: Wind Projects | B5: =COUNTIF('Master Data'!C3:C77,"Wind") -> 20
A6: Commissioned | B6: =COUNTIF('Master Data'!H3:H77,"Commissioned") -> 40
A7: Ongoing | B7: =COUNTIF('Master Data'!H3:H77,"Ongoing") -> 27
A8: Planned | B8: =COUNTIF('Master Data'!H3:H77,"Planned") -> 8
A9: Total Capacity (MW) | B9: =SUMIF('Master Data'!H3:H77,"Commissioned",'Master Data'!F3:F77) -> 7900
A10: Total Budget Allocated (₹ Cr) | B10: =SUM('Master Data'!I3:I77) -> 76012.84
A11: Total Budget Used (₹ Cr) | B11: =SUM('Master Data'!J3:J77) -> 54099.64
A12: Total Revenue (₹ Cr) | B12: =SUM('Master Data'!L3:L77) -> 9045.97
A14: Projects by State
A15: State | B15: Projects | C15: Total Capacity (MW) | D15: Total Budget (₹ Cr)
A16: Andhra Pradesh | B16: =COUNTIF('Master Data'!E3:E77,"Andhra Pradesh") -> 8 | C16: =SUMIF('Master Data'!E3:E77,"Andhra Pradesh",'Master Data'!F3:F77) -> 1800 | D16: =SUMIF('Master Data'!E3:E77,"Andhra Pradesh",'Master Data'!I3:I77) -> 8597.08
A17: Gujarat | B17: =COUNTIF('Master Data'!E3:E77,"Gujarat") -> 21 | C17: =SUMIF('Master Data'!E3:E77,"Gujarat",'Master Data'!F3:F77) -> 4150 | D17: =SUMIF('Master Data'!E3:E77,"Gujarat",'Master Data'!I3:I77) -> 19555.54
A18: Karnataka | B18: =COUNTIF('Master Data'!E3:E77,"Karnataka") -> 13 | C18: =SUMIF('Master Data'!E3:E77,"Karnataka",'Master Data'!F3:F77) -> 2800 | D18: =SUMIF('Master Data'!E3:E77,"Karnataka",'Master Data'!I3:I77) -> 13887.51
A19: Maharashtra | B19: =COUNTIF('Master Data'!E3:E77,"Maharashtra") -> 8 | C19: =SUMIF('Master Data'!E3:E77,"Maharashtra",'Master Data'!F3:F77) -> 1600 | D19: =SUMIF('Master Data'!E3:E77,"Maharashtra",'Master Data'!I3:I77) -> 7586.45
A20: Rajasthan | B20: =COUNTIF('Master Data'!E3:E77,"Rajasthan") -> 25 | C20: =SUMIF('Master Data'!E3:E77,"Rajasthan",'Master Data'!F3:F77) -> 5400 | D20: =SUMIF('Master Data'!E3:E77,"Rajasthan",'Master Data'!I3:I77) -> 26386.26

Sheet Ongoing Tracker
A1: AGEL — Ongoing Projects Tracker
A2: Project ID | B2: Project Name | C2: Location | D2: State | E2: Capacity (MW) | F2: FY Year | G2: Budget Allocated (₹ Cr) | H2: Budget Used (₹ Cr) | I2: Scheduled Comm. Date | J2: Expected Comm. Date | K2: Contractor Name | L2: Material Status | M2: Contractor Payment Status | N2: Project Completion (%) | O2: Remarks
A3: AGEL-S-031 | B3: Bikaner Solar Park – 50MW | C3: Bikaner | D3: Rajasthan | E3: 50 | F3: FY2025-26 | G3: 250.24 | H3: 163.73 | I3: 26-Feb-2026 | J3: 19-Oct-2026 | K3: Tata Projects Ltd | L3: Partially Delivered – 25% | M3: 50% Paid – Milestone 2 Pending | N3: 0.51 | O3: Land acquisition in progress
A4: AGEL-S-032 | B4: Pavagada Solar Park – 500MW | C4: Pavagada | D4: Karnataka | E4: 500 | F4: FY2025-26 | G4: 2615.4 | H4: 1907.22 | I4: 25-Dec-2025 | J4: 12-Apr-2026 | K4: Goldi Solar Pvt Ltd | L4: Partially Delivered – 75% | M4: 50% Paid – Milestone 2 Pending | N4: 0.48 | O4: Transmission line work pending
A5: AGEL-S-033 | B5: Dhule Solar Phase 2 – 100MW | C5: Dhule | D5: Maharashtra | E5: 100 | F5: FY2025-26 | G5: 459.95 | H5: 363.19 | I5: 19-Oct-2026 | J5: 28-Mar-2027 | K5: Waaree Energies Ltd | L5: Partially Delivered – 75% | M5: 75% Paid – Balance on Completion | N5: 0.62 | O5: Transmission line work pending
A6: AGEL-S-034 | B6: Barmer Solar Park – 50MW | C6: Barmer | D6: Rajasthan | E6: 50 | F6: FY2025-26 | G6: 258.98 | H6: 126.9 | I6: 20-Dec-2025 | J6: 24-Jul-2026 | K6: Genus Power Infrastructures | L6: Partially Delivered – 75% | M6: 10% Mobilisation Advance Paid | N6: 0.85 | O6: Transmission line work pending
A7: AGEL-S-035 | B7: Khavda Solar Phase 1 – 50MW | C7: Khavda | D7: Gujarat | E7: 50 | F7: FY2024-25 | G7: 205.25 | H7: 126.3 | I7: 08-Jan-2026 | J7: 28-May-2026 | K7: Tata Projects Ltd | L7: PO Raised – Awaiting Dispatch | M7: 30% Paid – Advance Released | N7: 0.62 | O7: Transmission line work pending
A8: AGEL-S-036 | B8: Fatehgarh Solar Park – 400MW | C8: Fatehgarh | D8: Rajasthan | E8: 400 | F8: FY2025-26 | G8: 1715.1 | H8: 1056.01 | I8: 22-Jul-2026 | J8: 22-Sep-2026 | K8: Genus Power Infrastructures | L8: Partially Delivered – 50% | M8: Payment on Hold – Dispute | N8: 0.68 | O8: Turbine erection in progress
A9: AGEL-S-037 | B9: Tumkur Solar Park – 50MW | C9: Tumkur | D9: Karnataka | E9: 50 | F9: FY2024-25 | G9: 243.5 | H9: 148.56 | I9: 17-Mar-2026 | J9: 03-Nov-2026 | K9: KEC International | L9: In Transit | M9: 10% Mobilisation Advance Paid | N9: 0.79 | O9: Statutory approvals awaited
A10: AGEL-S-038 | B10: Chitradurga Solar Phase 2 – 150MW | C10: Chitradurga | D10: Karnataka | E10: 150 | F10: FY2025-26 | G10: 814.2 | H10: 308.73 | I10: 06-Apr-2025 | J10: 01-Dec-2025 | K10: L&T Construction | L10: Partially Delivered – 50% | M10: 50% Paid – Milestone 2 Pending | N10: 0.59 | O10: Land acquisition in progress
A11: AGEL-S-039 | B11: Pokhran Solar Phase 3 – 200MW | C11: Pokhran | D11: Rajasthan | E11: 200 | F11: FY2024-25 | G11: 1065.84 | H11: 603.93 | I11: 12-Apr-2026 | J11: 26-Aug-2026 | K11: KEC International | L11: In Transit | M11: 10% Mobilisation Advance Paid | N11: 0.69 | O11: Land acquisition in progress
A12: AGEL-S-040 | B12: Jodhpur Solar Phase 1 – 100MW | C12: Jodhpur | D12: Rajasthan | E12: 100 | F12: FY2024-25 | G12: 469.68 | H12: 261.41 | I12: 14-Dec-2026 | J12: 25-May-2027 | K12: Montecarlo Ltd | L12: In Transit | M12: 50% Paid – Milestone 2 Pending | N12: 0.35 | O12: Financial closure in progress
A13: AGEL-S-041 | B13: Mundra Solar Phase 3 – 500MW | C13: Mundra | D13: Gujarat | E13: 500 | F13: FY2025-26 | G13: 2672.91 | H13: 1761.48 | I13: 16-Jul-2026 | J13: 07-Dec-2026 | K13: KEC International | L13: In Transit | M13: 30% Paid – Advance Released | N13: 0.8 | O13: Statutory approvals awaited
A14: AGEL-S-042 | B14: Patan Solar Park – 200MW | C14: Patan | D14: Gujarat | E14: 200 | F14: FY2024-25 | G14: 881.51 | H14: 375.38 | I14: 20-Oct-2025 | J14: 18-Jan-2026 | K14: KEC International | L14: Partially Delivered – 50% | M14: 50% Paid – Milestone 2 Pending | N14: 0.3 | O14: Civil work ongoing
... A37: AGEL-W-075 | B37: Jodhpur Wind Park – 200MW | C37: Jodhpur | D37: Rajasthan | E37: 200 | F37: FY2026-27 | G37: 874.79 | H37: 57.28 | I37: 16-Jan-2026 | J37: 26-Sep-2026 | K37: GE Vernova India | L37: PO Raised – Awaiting Dispatch | M37: Invoice Raised – Awaiting Approval | N37: 0.04 | O37: Turbine erection in progress

Sheet Material & Payment
A1: AGEL — Material & Contractor Payment Status
A2: Project ID | B2: Project Name | C2: Project Type | D2: Contractor Name | E2: Material (Module/Turbine) | F2: Material Status | G2: Budget Allocated (₹ Cr) | H2: Contractor Payment Status | I2: Project Completion (%) | J2: Category
A3: AGEL-S-001 | B3: Tumkur Solar Phase 3 – 200MW | C3: Solar | D3: Goldi Solar Pvt Ltd | E3: JA Solar (545W DeepBlue) | F3: Fully Delivered | G3: 983.75 | H3: Fully Paid | I3: 1 | J3: Commissioned
A4: AGEL-S-002 | B4: Chitradurga Solar Park – 250MW | C4: Solar | D4: Sterling and Wilson Pvt Ltd | E4: Jinko Solar (545W Tiger Neo) | F4: Fully Delivered | G4: 1201.97 | H4: 75% Paid – Balance on Completion | I4: 1 | J4: Commissioned
A5: AGEL-S-003 | B5: Pokhran Solar Phase 2 – 100MW | C5: Solar | D5: Sterling and Wilson Pvt Ltd | E5: Trina Solar (550W Vertex) | F5: Fully Delivered | G5: 518.96 | H5: Fully Paid | I5: 1 | J5: Commissioned
A6: AGEL-S-004 | B6: Jodhpur Solar Phase 1 – 250MW | C6: Solar | D6: KEC International | E6: LONGi Solar (555W Hi-MO6) | F6: Fully Delivered | G6: 1231.36 | H6: 75% Paid – Balance on Completion | I6: 1 | J6: Commissioned
A7: AGEL-S-005 | B7: Mundra Solar Phase 1 – 100MW | C7: Solar | D7: Vikram Solar Ltd | E7: Waaree Energies (550W Mono PERC) | F7: Fully Delivered | G7: 493.96 | H7: Fully Paid | I7: 1 | J7: Commissioned
A8: AGEL-S-006 | B8: Patan Solar Phase 2 – 200MW | C8: Solar | D8: KEC International | E8: Jinko Solar (545W Tiger Neo) | F8: Fully Delivered | G8: 907.51 | H8: 75% Paid – Balance on Completion | I8: 1 | J8: Commissioned
A9: AGEL-S-007 | B9: Osmanabad Solar Phase 3 – 400MW | C9: Solar | D9: Genus Power Infrastructures | E9: Canadian Solar (550W HiKu7) | F9: Fully Delivered | G9: 1769.36 | H9: 75% Paid – Balance on Completion | I9: 1 | J9: Commissioned
A10: AGEL-S-008 | B10: Morbi Solar Park – 300MW | C10: Solar | D10: Goldi Solar Pvt Ltd | E10: REC Group (405W Alpha Pure-R) | F10: Fully Delivered | G10: 1303.64 | H10: Fully Paid | I10: 1 | J10: Commissioned
A11: AGEL-S-009 | B11: Anantapur Solar Park – 100MW | C11: Solar | D11: SPML Infra Ltd | E11: LONGi Solar (555W Hi-MO6) | F11: Fully Delivered | G11: 460.23 | H11: Fully Paid | I11: 1 | J11: Commissioned
A12: AGEL-S-010 | B12: Rann of Kutch Solar Park – 300MW | C12: Solar | D12: SPML Infra Ltd | E12: Adani Solar (540W TOPCon) | F12: Fully Delivered | G12: 1261.56 | H12: Fully Paid | I12: 1 | J12: Commissioned
A13: AGEL-S-011 | B13: Jaisalmer Solar Phase 3 – 250MW | C13: Solar | D13: Genus Power Infrastructures | E13: JA Solar (545W DeepBlue) | F13: Fully Delivered | G13: 1199.57 | H13: Fully Paid | I13: 1 | J13: Commissioned
A14: AGEL-S-012 | B14: Kurnool Solar Park – 500MW | C14: Solar | D14: Montecarlo Ltd | E14: Adani Solar (540W TOPCon) | F14: Fully Delivered | G14: 2146.34 | H14: Fully Paid | I14: 1 | J14: Commissioned
... A77: AGEL-W-075 | B77: Jodhpur Wind Park – 200MW | C77: Wind | D77: GE Vernova India | E77: Enercon E-160 EP5 | F77: PO Raised – Awaiting Dispatch | G77: 874.79 | H77: Invoice Raised – Awaiting Approval | I77: 0.04 | J77: Planned
